sample_test_run.txt
BUY GFD 800 10 one
BUY GFD 700 10 one
PRINT
SELL IOC 750 10 two
PRINT
BUY GFD 900 10 two
SELL GFD 1000 1 three
PRINT

BUY GFD 1001 1 four
SELL GFD 1002 5 one
PRINT
MODIFY one BUY 1002 5
PRINT
SELL IOC 900 3 three
PRINT
